<mujoco model="h1_2">
  <compiler angle="radian" meshdir="meshes/" autolimits="true"/>

  <default>
    <joint damping="1" armature="0.1"  frictionloss="0.2" />
  </default>

  


  <asset>

    <material name="silver" rgba="0.7 0.7 0.7 1"/>
    <material name="black" rgba="0.2 0.2 0.2 1"/>

    <mesh name="pelvis" file="pelvis.STL"/>
    <mesh name="left_hip_yaw_link" file="left_hip_yaw_link.STL"/>
    <mesh name="left_hip_pitch_link" file="left_hip_pitch_link.STL"/>
    <mesh name="left_hip_roll_link" file="left_hip_roll_link.STL"/>
    <mesh name="left_knee_link" file="left_knee_link.STL"/>
    <mesh name="left_ankle_pitch_link" file="left_ankle_pitch_link.STL"/>
    <mesh name="left_ankle_roll_link" file="left_ankle_roll_link.STL"/>
    <mesh name="right_hip_yaw_link" file="right_hip_yaw_link.STL"/>
    <mesh name="right_hip_pitch_link" file="right_hip_pitch_link.STL"/>
    <mesh name="right_hip_roll_link" file="right_hip_roll_link.STL"/>
    <mesh name="right_knee_link" file="right_knee_link.STL"/>
    <mesh name="right_ankle_pitch_link" file="right_ankle_pitch_link.STL"/>
    <mesh name="right_ankle_roll_link" file="right_ankle_roll_link.STL"/>
    <mesh name="torso_link" file="torso_link.STL"/>
    <mesh name="left_shoulder_pitch_link" file="left_shoulder_pitch_link.STL"/>
    <mesh name="left_shoulder_roll_link" file="left_shoulder_roll_link.STL"/>
    <mesh name="left_shoulder_yaw_link" file="left_shoulder_yaw_link.STL"/>
    <mesh name="left_elbow_link" file="left_elbow_link.STL"/>
    <mesh name="left_wrist_roll_link" file="left_wrist_roll_link.STL"/>
    <mesh name="left_wrist_pitch_link" file="left_wrist_pitch_link.STL"/>
    <mesh name="wrist_yaw_link" file="wrist_yaw_link.STL"/>
    <mesh name="right_shoulder_pitch_link" file="right_shoulder_pitch_link.STL"/>
    <mesh name="right_shoulder_roll_link" file="right_shoulder_roll_link.STL"/>
    <mesh name="right_shoulder_yaw_link" file="right_shoulder_yaw_link.STL"/>
    <mesh name="right_elbow_link" file="right_elbow_link.STL"/>
    <mesh name="right_wrist_roll_link" file="right_wrist_roll_link.STL"/>
    <mesh name="right_wrist_pitch_link" file="right_wrist_pitch_link.STL"/>
    <mesh name="logo_link" file="logo_link.STL"/>


     <!-- ── Meshes mano derecha── -->
    <mesh name="R_hand_base_link" file="R_hand_base_link.STL"/>
    <mesh name="Link11_R" file="Link11_R.STL"/>
    <mesh name="Link12_R" file="Link12_R.STL"/>
    <mesh name="Link13_R" file="Link13_R.STL"/>
    <mesh name="Link14_R" file="Link14_R.STL"/>
    <mesh name="Link15_R" file="Link15_R.STL"/>
    <mesh name="Link16_R" file="Link16_R.STL"/>
    <mesh name="Link17_R" file="Link17_R.STL"/>
    <mesh name="Link18_R" file="Link18_R.STL"/>
    <mesh name="Link19_R" file="Link19_R.STL"/>
    <mesh name="Link20_R" file="Link20_R.STL"/>
    <mesh name="Link21_R" file="Link21_R.STL"/>
    <mesh name="Link22_R" file="Link22_R.STL"/>
    <!-- ── Meshes mano izquierda── -->
    <mesh name="L_hand_base_link" file="L_hand_base_link.STL"/>
    <mesh name="Link11_L" file="Link11_L.STL"/>
    <mesh name="Link12_L" file="Link12_L.STL"/>
    <mesh name="Link13_L" file="Link13_L.STL"/>
    <mesh name="Link14_L" file="Link14_L.STL"/>
    <mesh name="Link15_L" file="Link15_L.STL"/>
    <mesh name="Link16_L" file="Link16_L.STL"/>
    <mesh name="Link17_L" file="Link17_L.STL"/>
    <mesh name="Link18_L" file="Link18_L.STL"/>
    <mesh name="Link19_L" file="Link19_L.STL"/>
    <mesh name="Link20_L" file="Link20_L.STL"/>
    <mesh name="Link21_L" file="Link21_L.STL"/>
    <mesh name="Link22_L" file="Link22_L.STL"/>


  </asset>

  <worldbody>
    <body name="pelvis" pos="0 0 1.03">
      <inertial pos="-0.0004 3.7e-05 -0.046864" quat="0.497097 0.496809 -0.503132 0.502925" mass="5.983" diaginertia="0.0531565 0.0491678 0.00902583"/>
      <joint name="floating_base_joint" type="free" limited="false" actuatorfrclimited="false"/>
      <geom type="mesh" contype="0" conaffinity="0" group="1" density="0" rgba="0.1 0.1 0.1 1" mesh="pelvis"/>
      <geom size="0.05" rgba="0.1 0.1 0.1 1"/>
      <body name="left_hip_yaw_link" pos="0 0.0875 -0.1632">
        <inertial pos="0 -0.026197 0.006647" quat="0.704899 -0.0553755 0.0548434 0.705013" mass="2.829" diaginertia="0.00574303 0.00455361 0.00349461"/>
        <joint name="left_hip_yaw_joint" pos="0 0 0" axis="0 0 1" range="-0.43 0.43" actuatorfrcrange="-200 200"/>
        <geom type="mesh" contype="0" conaffinity="0" group="1" density="0" rgba="0.1 0.1 0.1 1" mesh="left_hip_yaw_link"/>
        <body name="left_hip_pitch_link" pos="0 0.0755 0">
          <inertial pos="-0.00781 -0.004724 -6.3e-05" quat="0.701575 0.711394 0.0330266 0.0249149" mass="2.92" diaginertia="0.00560661 0.00445055 0.00385068"/>
          <joint name="left_hip_pitch_joint" pos="0 0 0" axis="0 1 0" range="-3.14 2.5" actuatorfrcrange="-200 200"/>
          <geom type="mesh" contype="0" conaffinity="0" group="1" density="0" rgba="0.1 0.1 0.1 1" mesh="left_hip_pitch_link"/>
          <geom type="mesh" rgba="0.1 0.1 0.1 1" mesh="left_hip_pitch_link"/>
          <body name="left_hip_roll_link">
            <inertial pos="0.004171 -0.008576 -0.194509" quat="0.634842 0.0146079 0.0074063 0.772469" mass="4.962" diaginertia="0.0480229 0.0462788 0.00887409"/>
            <joint name="left_hip_roll_joint" pos="0 0 0" axis="1 0 0" range="-0.43 3.14" actuatorfrcrange="-200 200"/>
            <geom type="mesh" contype="0" conaffinity="0" group="1" density="0" rgba="0.1 0.1 0.1 1" mesh="left_hip_roll_link"/>
            <geom type="mesh" rgba="0.1 0.1 0.1 1" mesh="left_hip_roll_link"/>
            <body name="left_knee_link" pos="0 0 -0.4">
              <inertial pos="0.000179 0.000121 -0.168936" quat="0.416585 0.0104983 0.00514003 0.909021" mass="3.839" diaginertia="0.0391044 0.038959 0.00501125"/>
              <joint name="left_knee_joint" pos="0 0 0" axis="0 1 0" range="-0.12 2.19" actuatorfrcrange="-300 300"/>
              <geom type="mesh" contype="0" conaffinity="0" group="1" density="0" rgba="0.1 0.1 0.1 1" mesh="left_knee_link"/>
              <geom size="0.04 0.1" pos="0 0 -0.2" type="cylinder" rgba="0.1 0.1 0.1 1"/>
              <body name="left_ankle_pitch_link" pos="0 0 -0.4">
                <inertial pos="-0.000294 0 -0.010794" quat="0.999984 0 -0.00574445 0" mass="0.102" diaginertia="2.39454e-05 2.1837e-05 1.34126e-05"/>
                <joint name="left_ankle_pitch_joint" pos="0 0 0" axis="0 1 0" range="-0.897334 0.523598" actuatorfrcrange="-60 60"/>
                <geom type="mesh" contype="0" conaffinity="0" group="1" density="0" rgba="0.1 0.1 0.1 1" mesh="left_ankle_pitch_link"/>
                <body name="left_ankle_roll_link" pos="0 0 -0.02">
                  <site name="left_foot" pos="0.04 0 -0.037" size="0.01" rgba="1 0 0 1"/>
                  <inertial pos="0.029589 0 -0.015973" quat="0 0.725858 0 0.687845" mass="0.747" diaginertia="0.00359178 0.00343534 0.000640307"/>
                  <joint name="left_ankle_roll_joint" pos="0 0 0" axis="1 0 0" range="-0.261799 0.261799" actuatorfrcrange="-40 40"/>
                  <geom type="mesh" contype="0" conaffinity="0" group="1" density="0" rgba="0.1 0.1 0.1 1" mesh="left_ankle_roll_link"/>
                  <geom type="mesh" rgba="0.1 0.1 0.1 1" mesh="left_ankle_roll_link"/>
                  <geom name="left_foot1_collision" type="capsule" size="0.01" fromto="0.1 -0.026 -0.025 0.05 -0.027 -0.025" contype="1" conaffinity="1" condim="3"/>
                  <geom name="left_foot2_collision" type="capsule" size="0.01" fromto="-0.044 -0.018 -0.025 0.123 -0.018 -0.025" contype="1" conaffinity="1" condim="3"/>
                  <geom name="left_foot3_collision" type="capsule" size="0.01" fromto="-0.052 -0.01 -0.025 0.13 -0.01 -0.025" contype="1" conaffinity="1" condim="3"/>
                  <geom name="left_foot4_collision" type="capsule" size="0.01" fromto="-0.054 0 -0.025 0.132 0 -0.025" contype="1" conaffinity="1" condim="3"/>
                  <geom name="left_foot5_collision" type="capsule" size="0.01" fromto="-0.052 0.01 -0.025 0.13 0.01 -0.025" contype="1" conaffinity="1" condim="3"/>
                  <geom name="left_foot6_collision" type="capsule" size="0.01" fromto="-0.044 0.018 -0.025 0.123 0.018 -0.025" contype="1" conaffinity="1" condim="3"/>
                  <geom name="left_foot7_collision" type="capsule" size="0.01" fromto="0.1 0.026 -0.025 0.05 0.026 -0.025" contype="1" conaffinity="1" condim="3"/>
                </body>
              </body>
            </body>
          </body>
        </body>
      </body>
      <body name="right_hip_yaw_link" pos="0 -0.0875 -0.1632">
        <inertial pos="0 0.026197 0.006647" quat="0.705013 0.0548434 -0.0553755 0.704899" mass="2.829" diaginertia="0.00574303 0.00455361 0.00349461"/>
        <joint name="right_hip_yaw_joint" pos="0 0 0" axis="0 0 1" range="-0.43 0.43" actuatorfrcrange="-200 200"/>
        <geom type="mesh" contype="0" conaffinity="0" group="1" density="0" rgba="0.1 0.1 0.1 1" mesh="right_hip_yaw_link"/>
        <body name="right_hip_pitch_link" pos="0 -0.0755 0">
          <inertial pos="-0.00781 0.004724 -6.3e-05" quat="0.711394 0.701575 -0.0249149 -0.0330266" mass="2.92" diaginertia="0.00560661 0.00445055 0.00385068"/>
          <joint name="right_hip_pitch_joint" pos="0 0 0" axis="0 1 0" range="-3.14 2.5" actuatorfrcrange="-200 200"/>
          <geom type="mesh" contype="0" conaffinity="0" group="1" density="0" rgba="0.1 0.1 0.1 1" mesh="right_hip_pitch_link"/>
          <geom type="mesh" rgba="0.1 0.1 0.1 1" mesh="right_hip_pitch_link"/>
          <body name="right_hip_roll_link">
            <inertial pos="0.004171 0.008576 -0.194509" quat="0.772469 0.0074063 0.0146079 0.634842" mass="4.962" diaginertia="0.0480229 0.0462788 0.00887409"/>
            <joint name="right_hip_roll_joint" pos="0 0 0" axis="1 0 0" range="-3.14 0.43" actuatorfrcrange="-200 200"/>
            <geom type="mesh" contype="0" conaffinity="0" group="1" density="0" rgba="0.1 0.1 0.1 1" mesh="right_hip_roll_link"/>
            <geom type="mesh" rgba="0.1 0.1 0.1 1" mesh="right_hip_roll_link"/>
            <body name="right_knee_link" pos="0 0 -0.4">
              <inertial pos="0.000179 -0.000121 -0.168936" quat="0.909021 0.00514003 0.0104983 0.416585" mass="3.839" diaginertia="0.0391044 0.038959 0.00501125"/>
              <joint name="right_knee_joint" pos="0 0 0" axis="0 1 0" range="-0.12 2.19" actuatorfrcrange="-300 300"/>
              <geom type="mesh" contype="0" conaffinity="0" group="1" density="0" rgba="0.1 0.1 0.1 1" mesh="right_knee_link"/>
              <geom size="0.04 0.1" pos="0 0 -0.2" type="cylinder" rgba="0.1 0.1 0.1 1"/>
              <body name="right_ankle_pitch_link" pos="0 0 -0.4">
                <inertial pos="-0.000294 0 -0.010794" quat="0.999984 0 -0.00574445 0" mass="0.102" diaginertia="2.39454e-05 2.1837e-05 1.34126e-05"/>
                <joint name="right_ankle_pitch_joint" pos="0 0 0" axis="0 1 0" range="-0.897334 0.523598" actuatorfrcrange="-60 60"/>
                <geom type="mesh" contype="0" conaffinity="0" group="1" density="0" rgba="0.1 0.1 0.1 1" mesh="right_ankle_pitch_link"/>
                <body name="right_ankle_roll_link" pos="0 0 -0.02">
                  <site name="right_foot" pos="0.04 0 -0.037" size="0.01" rgba="1 0 0 1"/>
                  <inertial pos="0.029589 0 -0.015973" quat="0 0.725858 0 0.687845" mass="0.747" diaginertia="0.00359178 0.00343534 0.000640307"/>
                  <joint name="right_ankle_roll_joint" pos="0 0 0" axis="1 0 0" range="-0.261799 0.261799" actuatorfrcrange="-40 40"/>
                  <geom type="mesh" contype="0" conaffinity="0" group="1" density="0" rgba="0.1 0.1 0.1 1" mesh="right_ankle_roll_link"/>
                  <geom type="mesh" rgba="0.1 0.1 0.1 1" mesh="right_ankle_roll_link"/>
                  <geom name="right_foot1_collision" type="capsule" size="0.01" fromto="0.1 -0.026 -0.025 0.05 -0.026 -0.025" contype="1" conaffinity="1" condim="3"/>
                  <geom name="right_foot2_collision" type="capsule" size="0.01" fromto="-0.044 -0.018 -0.025 0.123 -0.018 -0.025" contype="1" conaffinity="1" condim="3"/>
                  <geom name="right_foot3_collision" type="capsule" size="0.01" fromto="-0.052 -0.01 -0.025 0.13 -0.01 -0.025" contype="1" conaffinity="1" condim="3"/>
                  <geom name="right_foot4_collision" type="capsule" size="0.01" fromto="-0.054 0 -0.025 0.132 0 -0.025" contype="1" conaffinity="1" condim="3"/>
                  <geom name="right_foot5_collision" type="capsule" size="0.01" fromto="-0.052 0.01 -0.025 0.13 0.01 -0.025" contype="1" conaffinity="1" condim="3"/>
                  <geom name="right_foot6_collision" type="capsule" size="0.01" fromto="-0.044 0.018 -0.025 0.123 0.018 -0.025" contype="1" conaffinity="1" condim="3"/>
                  <geom name="right_foot7_collision" type="capsule" size="0.01" fromto="0.1 0.026 -0.025 0.05 0.026 -0.025" contype="1" conaffinity="1" condim="3"/>
                </body>
              </body>
            </body>
          </body>
        </body>
      </body>
      <body name="torso_link">
        <inertial pos="0.000489 0.002797 0.20484" quat="0.999989 -0.00130808 -0.00282289 -0.00349105" mass="17.789" diaginertia="0.487315 0.409628 0.127837"/>
        <joint name="torso_joint" pos="0 0 0" axis="0 0 1" range="-2.35 2.35" actuatorfrcrange="-200 200"/>
        <geom type="mesh" contype="0" conaffinity="0" group="1" density="0" rgba="0.1 0.1 0.1 1" mesh="torso_link"/>
        <geom type="mesh" rgba="0.1 0.1 0.1 1" mesh="torso_link"/>
        <geom type="mesh" contype="0" conaffinity="0" group="1" density="0" rgba="1 1 1 1" mesh="logo_link"/>
        <site name="imu" size="0.01" pos="-0.04452 -0.01891 0.27756"/>
        <body name="left_shoulder_pitch_link" pos="0 0.14806 0.42333" quat="0.991445 0.130526 0 0">
          <inertial pos="0.003053 0.06042 -0.0059" quat="0.761799 0.645681 -0.0378496 -0.0363943" mass="1.327" diaginertia="0.000588757 0.00053309 0.000393023"/>
          <joint name="left_shoulder_pitch_joint" pos="0 0 0" axis="0 1 0" range="-3.14 1.57" actuatorfrcrange="-40 40"/>
          <geom type="mesh" contype="0" conaffinity="0" group="1" density="0" rgba="0.1 0.1 0.1 1" mesh="left_shoulder_pitch_link"/>
          <geom type="mesh" rgba="0.1 0.1 0.1 1" mesh="left_shoulder_pitch_link"/>
          <body name="left_shoulder_roll_link" pos="0.0342 0.061999 -0.0060011" quat="0.991445 -0.130526 0 0">
            <inertial pos="-0.030932 -1e-06 -0.10609" quat="0.986055 0.000456937 0.166408 0.00213553" mass="1.393" diaginertia="0.00200869 0.00193464 0.000449847"/>
            <joint name="left_shoulder_roll_joint" pos="0 0 0" axis="1 0 0" range="-0.38 3.4" actuatorfrcrange="-40 40"/>
            <geom type="mesh" contype="0" conaffinity="0" group="1" density="0" rgba="0.1 0.1 0.1 1" mesh="left_shoulder_roll_link"/>
            <geom type="mesh" rgba="0.1 0.1 0.1 1" mesh="left_shoulder_roll_link"/>
            <body name="left_shoulder_yaw_link" pos="-0.0342 0 -0.1456">
              <inertial pos="0.004583 0.001128 -0.001128" quat="0.663644 -0.0108866 -0.0267235 0.747492" mass="1.505" diaginertia="0.00431782 0.00420697 0.000645658"/>
              <joint name="left_shoulder_yaw_joint" pos="0 0 0" axis="0 0 1" range="-2.66 3.01" actuatorfrcrange="-18 18"/>
              <geom type="mesh" contype="0" conaffinity="0" group="1" density="0" rgba="0.1 0.1 0.1 1" mesh="left_shoulder_yaw_link"/>
              <geom type="mesh" rgba="0.1 0.1 0.1 1" mesh="left_shoulder_yaw_link"/>
              <body name="left_elbow_link" pos="0.006 0.0329 -0.182">
                <inertial pos="0.077092 -0.028751 -0.009714" quat="0.544921 0.610781 0.423352 0.388305" mass="0.691" diaginertia="0.000942091 0.000905273 0.00023025"/>
                <joint name="left_elbow_joint" pos="0 0 0" axis="0 1 0" range="-0.95 3.18" actuatorfrcrange="-18 18"/>
                <geom type="mesh" contype="0" conaffinity="0" group="1" density="0" rgba="0.1 0.1 0.1 1" mesh="left_elbow_link"/>
                <geom type="mesh" rgba="0.1 0.1 0.1 1" mesh="left_elbow_link"/>
                <body name="left_wrist_roll_link" pos="0.121 -0.0329 -0.011">
                  <inertial pos="0.035281 -0.00232 0.000337" quat="0.334998 0.622198 -0.240131 0.66557" mass="0.683" diaginertia="0.00034681 0.000328248 0.000294628"/>
                  <joint name="left_wrist_roll_joint" pos="0 0 0" axis="1 0 0" range="-3.01 2.75" actuatorfrcrange="-19 19"/>
                  <geom type="mesh" contype="0" conaffinity="0" group="1" density="0" rgba="0.1 0.1 0.1 1" mesh="left_wrist_roll_link"/>
                  <geom type="mesh" rgba="0.1 0.1 0.1 1" mesh="left_wrist_roll_link"/>
                  <body name="left_wrist_pitch_link" pos="0.087 0 0">
                    <inertial pos="0.020395 3.6e-05 -0.002973" quat="0.915893 -0.228405 -0.327262 -0.0432527" mass="0.484" diaginertia="7.25675e-05 7.00325e-05 6.9381e-05"/>
                    <joint name="left_wrist_pitch_joint" pos="0 0 0" axis="0 1 0" range="-0.4625 0.4625" actuatorfrcrange="-19 19"/>
                    <geom type="mesh" contype="0" conaffinity="0" group="1" density="0" rgba="0.1 0.1 0.1 1" mesh="left_wrist_pitch_link"/>
                    <geom type="mesh" rgba="0.1 0.1 0.1 1" mesh="left_wrist_pitch_link"/>
                    <body name="left_wrist_yaw_link" pos="0.02 0 0">
                      <inertial pos="0.027967 9.6e-05 0.000739" quat="0.704961 -0.0198461 -0.019614 0.708697" mass="0.124" diaginertia="0.000169999 0.000137463 8.46436e-05"/>
                      <joint name="left_wrist_yaw_joint" pos="0 0 0" axis="0 0 1" range="-1.27 1.27" actuatorfrcrange="-19 19"/>
                      <geom type="mesh" contype="0" conaffinity="0" group="1" density="0" rgba="0.1 0.1 0.1 1" mesh="wrist_yaw_link"/>
                      <!-- Site de attachment para mano Inspire -->
                          <site name="left_wrist_attach" pos="0.046 0 0" size="0.005" rgba="1 0 0 1"/>
                          <body name="left_hand_frame" pos="0.04 0 0" euler="0 0 1.5708">
                            <inertial mass="0.001" pos="0 0 0" diaginertia="1e-6 1e-6 1e-6"/>
                          <!-- ── Base de la mano ─────────────────────────────────────────── -->
                            <body name="L_hand_base_link" pos="0 0 0" euler="0 0 0">
                            <inertial pos="-0.002551 -0.066047 -0.0019357" mass="0.14143"
                                        fullinertia="0.0001234 8.3835e-05 7.7231e-05 2.1995e-06 -1.7694e-06 1.5968e-06"/>
                            <!-- Visual -->
                            <geom name="L_hand_base_visual" type="mesh" mesh="L_hand_base_link"
                                    contype="0" conaffinity="0" group="1" rgba="0.8 0.8 0.8 1"/>
                            <!-- Colisión base (cápsula simplificada) -->
                            <geom name="L_hand_base_col" type="capsule" size="0.018" fromto="0 -0.04 0  0 -0.1 0"
                                    rgba="0.2 0.8 0.2 0"/>

                            <!-- ── PULGAR ──────────────────────────────────────────────── -->
                            <body name="L_thumb_proximal_base" pos="-0.01696 -0.0691 0.02045"
                                    quat="0.499998 0.5 -0.5 0.500002">
                                <inertial pos="0.0048817 0.00038782 -0.00722" mass="0.0018869"
                                        diaginertia="8.66031e-08 6.87331e-08 4.94199e-08"/>
                                <joint name="L_thumb_proximal_yaw_joint" axis="0 0 1"
                                    range="-0.1 1.3" damping="0.05" frictionloss="0.01"/>
                                <geom type="mesh" mesh="Link11_L" contype="0" conaffinity="0" group="1" rgba="0.8 0.8 0.8 1"/>
                                <geom type="capsule" size="0.007" fromto="0 0 0  0.01 0.01 -0.009"
                                    rgba="0.2 0.8 0.2 0"/>

                                <body name="L_thumb_proximal" pos="0.0099867 0.0098242 -0.0089"
                                    quat="0.704571 -0.704573 -0.0598169 0.0598167">
                                <inertial pos="0.021936 -0.01279 -0.0080386" mass="0.0066101"
                                            diaginertia="2.78701e-06 2.44024e-06 8.6466e-07"/>
                                <joint name="L_thumb_proximal_pitch_joint" axis="0 0 -1"
                                        range="0 0.5" damping="0.05" frictionloss="0.01"/>
                                <geom type="mesh" mesh="Link12_L" contype="0" conaffinity="0" group="1" rgba="0.8 0.8 0.8 1"/>
                                <geom type="capsule" size="0.007" fromto="0 0 0  0.044 -0.035 -0.001"
                                        rgba="0.2 0.8 0.2 0"/>

                                <body name="L_thumb_intermediate" pos="0.04407 -0.034553 -0.0008">
                                    <inertial pos="0.0095531 0.0016282 -0.0072002" mass="0.0037844"
                                            diaginertia="4.6532e-07 4.48114e-07 2.45646e-07"/>
                                    <joint name="L_thumb_intermediate_joint" axis="0 0 -1"
                                        range="0 0.8" damping="0.05" frictionloss="0.01"/>
                                    <geom type="mesh" mesh="Link13_L" contype="0" conaffinity="0" group="1" rgba="0.8 0.8 0.8 1"/>
                                    <geom type="capsule" size="0.007" fromto="0 0 0  0.02 -0.01 -0.001"
                                        rgba="0.2 0.8 0.2 0"/>

                                    <body name="L_thumb_distal" pos="0.020248 -0.010156 -0.0012">
                                    <inertial pos="0.0092888 -0.004953 -0.0060033" mass="0.003344"
                                                diaginertia="2.0026e-07 1.95246e-07 8.1594e-08"/>
                                    <joint name="L_thumb_distal_joint" axis="0 0 -1"
                                            range="0 1.2" damping="0.05" frictionloss="0.01"/>
                                    <geom type="mesh" mesh="Link14_L" contype="0" conaffinity="0" group="1" rgba="0.8 0.8 0.8 1"/>
                                    <geom type="capsule" size="0.007" fromto="0 0 0  0.015 -0.013 -0.004"
                                            rgba="0.2 0.8 0.2 0"/>
                                    <!-- Fingertip site -->
                                    <site name="L_thumb_tip" pos="0.015 -0.013 -0.004" size="0.005" rgba="1 0 0 1"/>
                                    </body>
                                </body>
                                </body>
                            </body>

                            <!-- ── ÍNDICE ──────────────────────────────────────────────── -->
                            <body name="L_index_proximal" pos="0.00028533 -0.13653 0.032268"
                                    quat="0.999848 -0.0174526 0 0">
                                <inertial pos="0.0012971 -0.011934 -0.0059998" mass="0.0042405"
                                        diaginertia="6.9402e-07 6.62904e-07 2.10916e-07"/>
                                <joint name="L_index_proximal_joint" axis="0 0 -1"
                                    range="0 1.7" damping="0.05" frictionloss="0.01"/>
                                <geom type="mesh" mesh="Link15_L" contype="0" conaffinity="0" group="1" rgba="0.8 0.8 0.8 1"/>
                                <geom type="capsule" size="0.007" fromto="0 0 0  -0.002 -0.032 -0.001"
                                    rgba="0.2 0.8 0.2 0"/>

                                <body name="L_index_intermediate" pos="-0.0024229 -0.032041 -0.001">
                                <inertial pos="0.0021753 -0.019567 -0.005" mass="0.0045682"
                                            diaginertia="7.8176e-07 7.72427e-07 8.47209e-08"/>
                                <joint name="L_index_intermediate_joint" axis="0 0 -1"
                                        range="0 1.7" damping="0.05" frictionloss="0.01"/>
                                <geom type="mesh" mesh="Link16_L" contype="0" conaffinity="0" group="1" rgba="0.8 0.8 0.8 1"/>
                                <geom type="capsule" size="0.007" fromto="0 0 0  -0.005 -0.04 -0.004"
                                        rgba="0.2 0.8 0.2 0"/>
                                <site name="L_index_tip" pos="-0.005 -0.04 -0.004" size="0.005" rgba="0 1 0 1"/>
                                </body>
                            </body>

                            <!-- ── CORAZÓN ─────────────────────────────────────────────── -->
                            <body name="L_middle_proximal" pos="0.00028533 -0.1371 0.01295">
                                <inertial pos="0.0012971 -0.011934 -0.0059999" mass="0.0042405"
                                        diaginertia="6.9402e-07 6.62904e-07 2.10916e-07"/>
                                <joint name="L_middle_proximal_joint" axis="0 0 -1"
                                    range="0 1.7" damping="0.05" frictionloss="0.01"/>
                                <geom type="mesh" mesh="Link17_L" contype="0" conaffinity="0" group="1" rgba="0.8 0.8 0.8 1"/>
                                <geom type="capsule" size="0.007" fromto="0 0 0  -0.002 -0.032 -0.001"
                                    rgba="0.2 0.8 0.2 0"/>

                                <body name="L_middle_intermediate" pos="-0.0024229 -0.032041 -0.001">
                                <inertial pos="0.001921 -0.020796 -0.0049999" mass="0.0050397"
                                            diaginertia="9.8385e-07 9.73288e-07 9.14016e-08"/>
                                <joint name="L_middle_intermediate_joint" axis="0 0 -1"
                                        range="0 1.7" damping="0.05" frictionloss="0.01"/>
                                <geom type="mesh" mesh="Link18_L" contype="0" conaffinity="0" group="1" rgba="0.8 0.8 0.8 1"/>
                                <geom type="capsule" size="0.007" fromto="0 0 0  -0.005 -0.045 -0.004"
                                        rgba="0.2 0.8 0.2 0"/>
                                <site name="L_middle_tip" pos="-0.005 -0.045 -0.004" size="0.005" rgba="0 0 1 1"/>
                                </body>
                            </body>

                            <!-- ── ANULAR ───────────────────────────────────────────────── -->
                            <body name="L_ring_proximal" pos="0.00028533 -0.13691 -0.0062872"
                                    quat="0.999657 0.026177 0 0">
                                <inertial pos="0.0012971 -0.011934 -0.0059999" mass="0.0042405"
                                        diaginertia="6.9402e-07 6.62904e-07 2.10916e-07"/>
                                <joint name="L_ring_proximal_joint" axis="0 0 -1"
                                    range="0 1.7" damping="0.05" frictionloss="0.01"/>
                                <geom type="mesh" mesh="Link19_L" contype="0" conaffinity="0" group="1" rgba="0.8 0.8 0.8 1"/>
                                <geom type="capsule" size="0.007" fromto="0 0 0  -0.002 -0.032 -0.001"
                                    rgba="0.2 0.8 0.2 0"/>

                                <body name="L_ring_intermediate" pos="-0.0024229 -0.032041 -0.001">
                                <inertial pos="0.0021753 -0.019567 -0.005" mass="0.0045682"
                                            diaginertia="7.8176e-07 7.72437e-07 8.47208e-08"/>
                                <joint name="L_ring_intermediate_joint" axis="0 0 -1"
                                        range="0 1.7" damping="0.05" frictionloss="0.01"/>
                                <geom type="mesh" mesh="Link20_L" contype="0" conaffinity="0" group="1" rgba="0.8 0.8 0.8 1"/>
                                <geom type="capsule" size="0.007" fromto="0 0 0  -0.002 -0.04 -0.004"
                                        rgba="0.2 0.8 0.2 0"/>
                                <site name="L_ring_tip" pos="-0.002 -0.04 -0.004" size="0.005" rgba="0 1 1 1"/>
                                </body>
                            </body>

                            <!-- ── MEÑIQUE ─────────────────────────────────────────────── -->
                            <body name="L_pinky_proximal" pos="0.00028533 -0.13571 -0.025488"
                                    quat="0.99863 0.0523361 0 0">
                                <inertial pos="0.0012971 -0.011934 -0.0059999" mass="0.0042405"
                                        diaginertia="6.9402e-07 6.62904e-07 2.10916e-07"/>
                                <joint name="L_pinky_proximal_joint" axis="0 0 -1"
                                    range="0 1.7" damping="0.05" frictionloss="0.01"/>
                                <geom type="mesh" mesh="Link21_L" contype="0" conaffinity="0" group="1" rgba="0.8 0.8 0.8 1"/>
                                <geom type="capsule" size="0.007" fromto="0 0 0  -0.002 -0.032 -0.001"
                                    rgba="0.2 0.8 0.2 0"/>

                                <body name="L_pinky_intermediate" pos="-0.0024229 -0.032041 -0.001">
                                <inertial pos="0.0024788 -0.016208 -0.0050001" mass="0.0036036"
                                            diaginertia="4.4881e-07 4.43809e-07 6.5736e-08"/>
                                <joint name="L_pinky_intermediate_joint" axis="0 0 -1"
                                        range="0 1.7" damping="0.05" frictionloss="0.01"/>
                                <geom type="mesh" mesh="Link22_L" contype="0" conaffinity="0" group="1" rgba="0.8 0.8 0.8 1"/>
                                <geom type="capsule" size="0.007" fromto="0 0 0  -0.002 -0.032 -0.004"
                                        rgba="0.2 0.8 0.2 0"/>
                                <site name="L_pinky_tip" pos="-0.002 -0.032 -0.004" size="0.005" rgba="1 1 1 1"/>
                                </body>
                            </body>

                            </body>
                        </body>
                    
                    </body>
                  </body>
                </body>
              </body>
            </body>
          </body>
        </body>
        <body name="right_shoulder_pitch_link" pos="0 -0.14806 0.42333" quat="0.991445 -0.130526 0 0">
          <inertial pos="0.003053 -0.06042 -0.0059" quat="0.645681 0.761799 0.0363943 0.0378496" mass="1.327" diaginertia="0.000588757 0.00053309 0.000393023"/>
          <joint name="right_shoulder_pitch_joint" pos="0 0 0" axis="0 1 0" range="-3.14 1.57" actuatorfrcrange="-40 40"/>
          <geom type="mesh" contype="0" conaffinity="0" group="1" density="0" rgba="0.1 0.1 0.1 1" mesh="right_shoulder_pitch_link"/>
          <geom type="mesh" rgba="0.1 0.1 0.1 1" mesh="right_shoulder_pitch_link"/>
          <body name="right_shoulder_roll_link" pos="0.0342 -0.061999 -0.0060011" quat="0.991445 0.130526 0 0">
            <inertial pos="-0.030932 1e-06 -0.10609" quat="0.986055 -0.000456937 0.166408 -0.00213553" mass="1.393" diaginertia="0.00200869 0.00193464 0.000449847"/>
            <joint name="right_shoulder_roll_joint" pos="0 0 0" axis="1 0 0" range="-3.4 0.38" actuatorfrcrange="-40 40"/>
            <geom type="mesh" contype="0" conaffinity="0" group="1" density="0" rgba="0.1 0.1 0.1 1" mesh="right_shoulder_roll_link"/>
            <geom type="mesh" rgba="0.1 0.1 0.1 1" mesh="right_shoulder_roll_link"/>
            <body name="right_shoulder_yaw_link" pos="-0.0342 0 -0.1456">
              <inertial pos="0.004583 -0.001128 -0.001128" quat="0.747492 -0.0267235 -0.0108866 0.663644" mass="1.505" diaginertia="0.00431782 0.00420697 0.000645658"/>
              <joint name="right_shoulder_yaw_joint" pos="0 0 0" axis="0 0 1" range="-3.01 2.66" actuatorfrcrange="-18 18"/>
              <geom type="mesh" contype="0" conaffinity="0" group="1" density="0" rgba="0.1 0.1 0.1 1" mesh="right_shoulder_yaw_link"/>
              <geom type="mesh" rgba="0.1 0.1 0.1 1" mesh="right_shoulder_yaw_link"/>
              <body name="right_elbow_link" pos="0.006 -0.0329 -0.182">
                <inertial pos="0.077092 0.028751 -0.009714" quat="0.388305 0.423352 0.610781 0.544921" mass="0.691" diaginertia="0.000942091 0.000905273 0.00023025"/>
                <joint name="right_elbow_joint" pos="0 0 0" axis="0 1 0" range="-0.95 3.18" actuatorfrcrange="-18 18"/>
                <geom type="mesh" contype="0" conaffinity="0" group="1" density="0" rgba="0.1 0.1 0.1 1" mesh="right_elbow_link"/>
                <geom type="mesh" rgba="0.1 0.1 0.1 1" mesh="right_elbow_link"/>
                <body name="right_wrist_roll_link" pos="0.121 0.0329 -0.011">
                  <inertial pos="0.035281 -0.00232 0.000337" quat="0.334998 0.622198 -0.240131 0.66557" mass="0.683" diaginertia="0.00034681 0.000328248 0.000294628"/>
                  <joint name="right_wrist_roll_joint" pos="0 0 0" axis="1 0 0" range="-2.75 3.01" actuatorfrcrange="-19 19"/>
                  <geom type="mesh" contype="0" conaffinity="0" group="1" density="0" rgba="0.1 0.1 0.1 1" mesh="right_wrist_roll_link"/>
                  <geom type="mesh" rgba="0.1 0.1 0.1 1" mesh="right_wrist_roll_link"/>
                  <body name="right_wrist_pitch_link" pos="0.087 0 0">
                    <inertial pos="0.020395 3.6e-05 -0.002973" quat="0.915893 -0.228405 -0.327262 -0.0432527" mass="0.484" diaginertia="7.25675e-05 7.00325e-05 6.9381e-05"/>
                    <joint name="right_wrist_pitch_joint" pos="0 0 0" axis="0 1 0" range="-0.4625 0.4625" actuatorfrcrange="-19 19"/>
                    <geom type="mesh" contype="0" conaffinity="0" group="1" density="0" rgba="0.1 0.1 0.1 1" mesh="right_wrist_pitch_link"/>
                    <geom type="mesh" rgba="0.1 0.1 0.1 1" mesh="right_wrist_pitch_link"/>
                    <body name="right_wrist_yaw_link" pos="0.02 0 0">
                      <inertial pos="0.027967 -9.6e-05 0.000739" quat="0.708697 -0.019614 -0.0198461 0.704961" mass="0.124" diaginertia="0.000169999 0.000137463 8.46436e-05"/>
                      <joint name="right_wrist_yaw_joint" pos="0 0 0" axis="0 0 1" range="-1.27 1.27" actuatorfrcrange="-19 19"/>
                      <geom type="mesh" contype="0" conaffinity="0" group="1" density="0" rgba="0.1 0.1 0.1 1" mesh="wrist_yaw_link"/>
                    <!-- Site de attachment para mano Inspire -->
                          <site name="right_wrist_attach" pos="0.046 0 0" size="0.005" rgba="1 0 0 1"/>
                            <body name="right_hand_frame" pos="0.04 0 0" euler="0 0 1.5708">
                            <inertial mass="0.001" pos="0 0 0" diaginertia="1e-6 1e-6 1e-6"/>
                              <!-- ── Base de la mano ─────────────────────────────────────────── -->
                                <body name="R_hand_base_link" pos="0 0 0">
                                <body name="R_hand_rotated_180" pos="0 0 0" quat="0 0 1 0">
                                <inertial pos="-0.002551 -0.066047 0.0019357" mass="0.14143"
                                            fullinertia="0.0001234 8.3835e-05 7.7231e-05 2.1995e-06 1.7694e-06 1.5968e-06"/>
                                <!-- Visual -->
                                <geom name="R_hand_base_visual" type="mesh" mesh="R_hand_base_link"
                                        contype="0" conaffinity="0" group="1" rgba="0.8 0.8 0.8 1"/>
                                <!-- Colisión base (cápsula simplificada) -->
                                <geom name="R_hand_base_col" type="capsule" size="0.018" fromto="0 -0.04 0  0 -0.1 0"
                                        rgba="0.2 0.8 0.2 0"/>

                                <!-- ── PULGAR ──────────────────────────────────────────────── -->
                                <body name="R_thumb_proximal_base" pos="-0.01696 -0.0691 -0.02045"
                                        quat="0.499998 0.5 -0.5 0.500002">
                                    <inertial pos="-0.0048064 0.0009382 -0.00757" mass="0.0018869"
                                            diaginertia="8.66026e-08 6.8732e-08 4.94194e-08"/>
                                    <joint name="R_thumb_proximal_yaw_joint" axis="0 0 -1"
                                        range="-0.1 1.3" damping="0.05" frictionloss="0.01"/>
                                    <geom type="mesh" mesh="Link11_R" contype="0" conaffinity="0" group="1" rgba="0.8 0.8 0.8 1"/>
                                    <geom type="capsule" size="0.007" fromto="0 0 0  -0.009 0.011 -0.009"
                                        rgba="0.2 0.8 0.2 0"/>

                                    <body name="R_thumb_proximal" pos="-0.0088099 0.010892 -0.00925"
                                        quat="0.0996843 0.0996847 0.700046 0.700044">
                                    <inertial pos="0.021932 0.012785 -0.0080386" mass="0.0066075"
                                                diaginertia="2.78601e-06 2.43933e-06 8.64566e-07"/>
                                    <joint name="R_thumb_proximal_pitch_joint" axis="0 0 1"
                                            range="0 0.5" damping="0.05" frictionloss="0.01"/>
                                    <geom type="mesh" mesh="Link12_R" contype="0" conaffinity="0" group="1" rgba="0.8 0.8 0.8 1"/>
                                    <geom type="capsule" size="0.007" fromto="0 0 0  0.044 0.035 -0.001"
                                            rgba="0.2 0.8 0.2 0"/>

                                    <body name="R_thumb_intermediate" pos="0.04407 0.034553 -0.0008">
                                        <inertial pos="0.0095544 -0.0016282 -0.0071997" mass="0.0037847"
                                                diaginertia="4.6531e-07 4.48089e-07 2.45661e-07"/>
                                        <joint name="R_thumb_intermediate_joint" axis="0 0 1"
                                            range="0 0.8" damping="0.05" frictionloss="0.01"/>
                                        <geom type="mesh" mesh="Link13_R" contype="0" conaffinity="0" group="1" rgba="0.8 0.8 0.8 1"/>
                                        <geom type="capsule" size="0.007" fromto="0 0 0  0.02 0.01 -0.001"
                                            rgba="0.2 0.8 0.2 0"/>

                                        <body name="R_thumb_distal" pos="0.020248 0.010156 -0.0012">
                                        <inertial pos="0.0092888 0.0049529 -0.0060033" mass="0.0033441"
                                                    diaginertia="2.0026e-07 1.95247e-07 8.1593e-08"/>
                                        <joint name="R_thumb_distal_joint" axis="0 0 1"
                                                range="0 1.2" damping="0.05" frictionloss="0.01"/>
                                        <geom type="mesh" mesh="Link14_R" contype="0" conaffinity="0" group="1" rgba="0.8 0.8 0.8 1"/>
                                        <geom type="capsule" size="0.007" fromto="0 0 0  0.015 0.013 -0.004"
                                                rgba="0.2 0.8 0.2 0"/>
                                        <!-- Fingertip site -->
                                        <site name="R_thumb_tip" pos="0.015 0.013 -0.004" size="0.005" rgba="1 0 0 1"/>
                                        </body>
                                    </body>
                                    </body>
                                </body>

                                <!-- ── ÍNDICE ──────────────────────────────────────────────── -->
                                <body name="R_index_proximal" pos="0.00028533 -0.13653 -0.032268"
                                        quat="0.0174454 -0.999848 0 0">
                                    <inertial pos="0.0012259 0.011942 -0.0060001" mass="0.0042403"
                                            diaginertia="6.9398e-07 6.62871e-07 2.10909e-07"/>
                                    <joint name="R_index_proximal_joint" axis="0 0 1"
                                        range="0 1.7" damping="0.05" frictionloss="0.01"/>
                                    <geom type="mesh" mesh="Link15_R" contype="0" conaffinity="0" group="1" rgba="0.8 0.8 0.8 1"/>
                                    <geom type="capsule" size="0.007" fromto="0 0 0  -0.003 0.032 -0.001"
                                        rgba="0.2 0.8 0.2 0"/>

                                    <body name="R_index_intermediate" pos="-0.0026138 0.032026 -0.001">
                                    <inertial pos="0.0019697 0.019589 -0.005" mass="0.0045683"
                                                diaginertia="7.8179e-07 7.72465e-07 8.47212e-08"/>
                                    <joint name="R_index_intermediate_joint" axis="0 0 1"
                                            range="0 1.7" damping="0.05" frictionloss="0.01"/>
                                    <geom type="mesh" mesh="Link16_R" contype="0" conaffinity="0" group="1" rgba="0.8 0.8 0.8 1"/>
                                    <geom type="capsule" size="0.007" fromto="0 0 0  -0.005 0.04 -0.004"
                                            rgba="0.2 0.8 0.2 0"/>
                                    <site name="R_index_tip" pos="-0.005 0.04 -0.004" size="0.005" rgba="0 1 0 1"/>
                                    </body>
                                </body>

                                <!-- ── CORAZÓN ─────────────────────────────────────────────── -->
                                <body name="R_middle_proximal" pos="0.00028533 -0.1371 -0.01295"
                                        quat="-3.67321e-06 -1 0 0">
                                    <inertial pos="0.001297 0.011934 -0.0060001" mass="0.0042403"
                                            diaginertia="6.9397e-07 6.62865e-07 2.10915e-07"/>
                                    <joint name="R_middle_proximal_joint" axis="0 0 1"
                                        range="0 1.7" damping="0.05" frictionloss="0.01"/>
                                    <geom type="mesh" mesh="Link17_R" contype="0" conaffinity="0" group="1" rgba="0.8 0.8 0.8 1"/>
                                    <geom type="capsule" size="0.007" fromto="0 0 0  -0.002 0.032 -0.001"
                                        rgba="0.2 0.8 0.2 0"/>

                                    <body name="R_middle_intermediate" pos="-0.0024229 0.032041 -0.001">
                                    <inertial pos="0.001921 0.020796 -0.005" mass="0.0050396"
                                                diaginertia="9.8384e-07 9.73279e-07 9.14014e-08"/>
                                    <joint name="R_middle_intermediate_joint" axis="0 0 1"
                                            range="0 1.7" damping="0.05" frictionloss="0.01"/>
                                    <geom type="mesh" mesh="Link18_R" contype="0" conaffinity="0" group="1" rgba="0.8 0.8 0.8 1"/>
                                    <geom type="capsule" size="0.007" fromto="0 0 0  -0.005 0.045 -0.004"
                                            rgba="0.2 0.8 0.2 0"/>
                                    <site name="R_middle_tip" pos="-0.005 0.045 -0.004" size="0.005" rgba="0 0 1 1"/>
                                    </body>
                                </body>

                                <!-- ── ANULAR ───────────────────────────────────────────────── -->
                                <body name="R_ring_proximal" pos="0.00028533 -0.13691 0.0062872"
                                        quat="0.0261933 0.999657 0 0">
                                    <inertial pos="0.001297 0.011934 -0.0060002" mass="0.0042403"
                                            diaginertia="6.9397e-07 6.62865e-07 2.10915e-07"/>
                                    <joint name="R_ring_proximal_joint" axis="0 0 1"
                                        range="0 1.7" damping="0.05" frictionloss="0.01"/>
                                    <geom type="mesh" mesh="Link19_R" contype="0" conaffinity="0" group="1" rgba="0.8 0.8 0.8 1"/>
                                    <geom type="capsule" size="0.007" fromto="0 0 0  -0.002 0.032 -0.001"
                                        rgba="0.2 0.8 0.2 0"/>

                                    <body name="R_ring_intermediate" pos="-0.0024229 0.032041 -0.001">
                                    <inertial pos="0.0021753 0.019567 -0.005" mass="0.0045683"
                                                diaginertia="7.8177e-07 7.72448e-07 8.4722e-08"/>
                                    <joint name="R_ring_intermediate_joint" axis="0 0 1"
                                            range="0 1.7" damping="0.05" frictionloss="0.01"/>
                                    <geom type="mesh" mesh="Link20_R" contype="0" conaffinity="0" group="1" rgba="0.8 0.8 0.8 1"/>
                                    <geom type="capsule" size="0.007" fromto="0 0 0  -0.002 0.04 -0.004"
                                        rgba="0.2 0.8 0.2 0"/>
                                    <site name="R_ring_tip" pos="-0.002 0.04 -0.004" size="0.005" rgba="0 1 1 1"/>
                                    </body>
                                </body>

                                <!-- ── MEÑIQUE ─────────────────────────────────────────────── -->
                                <body name="R_pinky_proximal" pos="0.00028533 -0.13571 0.025488"
                                        quat="0.0523224 0.99863 0 0">
                                    <inertial pos="0.001297 0.011934 -0.0060001" mass="0.0042403"
                                            diaginertia="6.9397e-07 6.62865e-07 2.10915e-07"/>
                                    <joint name="R_pinky_proximal_joint" axis="0 0 1"
                                        range="0 1.7" damping="0.05" frictionloss="0.01"/>
                                    <geom type="mesh" mesh="Link21_R" contype="0" conaffinity="0" group="1" rgba="0.8 0.8 0.8 1"/>
                                    <geom type="capsule" size="0.007" fromto="0 0 0  -0.002 0.032 -0.001"
                                        rgba="0.2 0.8 0.2 0"/>

                                    <body name="R_pinky_intermediate" pos="-0.0024229 0.032041 -0.001">
                                    <inertial pos="0.0024748 0.016203 -0.0050031" mass="0.0035996"
                                                diaginertia="4.4867e-07 4.43723e-07 6.56538e-08"/>
                                    <joint name="R_pinky_intermediate_joint" axis="0 0 1"
                                            range="0 1.7" damping="0.05" frictionloss="0.01"/>
                                    <geom type="mesh" mesh="Link22_R" contype="0" conaffinity="0" group="1" rgba="0.8 0.8 0.8 1"/>
                                    <geom type="capsule" size="0.007" fromto="0 0 0  -0.002 0.032 -0.004"
                                        rgba="0.2 0.8 0.2 0"/>
                                    <site name="R_pinky_tip" pos="-0.002 0.032 -0.004" size="0.005" rgba="1 1 1 1"/>
                                    </body>
                                </body>

                                </body>
                                </body>
              
                    </body>
                  </body>
                </body>
              </body>
            </body>
          </body>
        </body>
      </body>
    </body>
  </body>
  </worldbody>













  <sensor>
    <framequat name="imu_quat" objtype="site" objname="imu" />
    <gyro name="imu_gyro" site="imu" />
    <gyro name="imu_ang_vel" site="imu" />
    <accelerometer name="imu_acc" site="imu" />
    <velocimeter name="imu_lin_vel" site="imu" />
    <subtreeangmom name="root_angmom" body="pelvis" />
    <framepos name="frame_pos" objtype="site" objname="imu" />
    <framelinvel name="frame_vel" objtype="site" objname="imu" />
  </sensor>
</mujoco>